<?xml version="1.0" ?>
<!-- =================================================================================== -->
<!-- |    This document was autogenerated by xacro from /home/jeremy/home2/install/frida_description/share/frida_description/urdf/TMR2025/FRIDA_Real.urdf.xacro | -->
<!-- |    EDITING THIS FILE BY HAND IS NOT RECOMMENDED                                 | -->
<!-- =================================================================================== -->
<robot name="FRIDA" xmlns:gz="http://gazebosim.org/schema">
  <material name="home_base_gray">
    <color rgba="0.752941176470588 0.752941176470588 0.752941176470588 1"/>
  </material>
  <material name="home_base_lidar">
    <color rgba="0.792156862745098 0.819607843137255 0.933333333333333 1"/>
  </material>
  <!-- =================== base_footprint (root) =================== -->
  <link name="_base_footprint"/>
  <joint name="_base_footprint_joint" type="fixed">
    <origin rpy="0 0 0" xyz="0 0 0.0385"/>
    <parent link="_base_footprint"/>
    <child link="_base_link"/>
  </joint>
  <!-- =================== base_link =================== -->
  <link name="_base_link">
    <inertial>
      <origin rpy="0 0 0" xyz="0.0035289 4.9532E-05 0.18881"/>
      <mass value="31.284"/>
      <inertia ixx="0.16472" ixy="6.3557E-05" ixz="0.00075615" iyy="0.12042" iyz="-0.0002185" izz="0.20341"/>
    </inertial>
    <visual>
      <origin rpy="0 0 0" xyz="0 0 0"/>
      <geometry>
        <mesh filename="package://home_custom_base_description/meshes/visual/base_link.STL"/>
      </geometry>
      <material name="home_base_gray"/>
    </visual>
    <collision>
      <origin rpy="0 0 0" xyz="0 0 0"/>
      <geometry>
        <mesh filename="package://home_custom_base_description/meshes/visual/base_link.STL"/>
      </geometry>
    </collision>
  </link>
  <!-- =================== wheel_FL =================== -->
  <link name="_wheel_FL">
    <inertial>
      <origin rpy="0 0 0" xyz="-2.01760275153617E-11 -1.2648801422932E-08 -0.000225751978378957"/>
      <mass value="0.316522165409144"/>
      <inertia ixx="0.00018550184297716" ixy="1.47011741018487E-13" ixz="2.37351682170515E-11" iyy="0.000185501841925862" iyz="3.06630872791257E-11" izz="0.000329540832812286"/>
    </inertial>
    <visual>
      <origin rpy="0 0 0" xyz="0 0 0"/>
      <geometry>
        <mesh filename="package://home_custom_base_description/meshes/visual/wheel.STL"/>
      </geometry>
      <material name="home_base_gray"/>
    </visual>
    <collision>
      <origin rpy="0 0 0" xyz="0 0 0"/>
      <geometry>
        <mesh filename="package://home_custom_base_description/meshes/visual/wheel.STL"/>
      </geometry>
    </collision>
  </link>
  <joint name="_wheel_FL_joint" type="continuous">
    <origin rpy="-1.5707963267949 0 0" xyz="0.184790699909997 0.219394995052441 0.0376959841787657"/>
    <parent link="_base_link"/>
    <child link="_wheel_FL"/>
    <axis xyz="0 0 1"/>
  </joint>
  <!-- =================== wheel_FR =================== -->
  <link name="_wheel_FR">
    <inertial>
      <origin rpy="0 0 0" xyz="1.08346649985158E-08 2.62530414074647E-09 -0.000243946115891319"/>
      <mass value="0.316802369656036"/>
      <inertia ixx="0.000185524626213339" ixy="3.28960054383515E-11" ixz="-3.31069057136383E-11" iyy="0.000185524577692034" iyz="1.46274884608806E-10" izz="0.000329541494389925"/>
    </inertial>
    <visual>
      <origin rpy="0 0 0" xyz="0 0 0"/>
      <geometry>
        <mesh filename="package://home_custom_base_description/meshes/visual/wheel.STL"/>
      </geometry>
      <material name="home_base_gray"/>
    </visual>
    <collision>
      <origin rpy="0 0 0" xyz="0 0 0"/>
      <geometry>
        <mesh filename="package://home_custom_base_description/meshes/visual/wheel.STL"/>
      </geometry>
    </collision>
  </link>
  <joint name="_wheel_FR_joint" type="continuous">
    <origin rpy="-1.5707963267949 0 0" xyz="0.184790699909996 -0.219395004947559 0.0376959841787653"/>
    <parent link="_base_link"/>
    <child link="_wheel_FR"/>
    <axis xyz="0 0 1"/>
  </joint>
  <!-- =================== wheel_RL =================== -->
  <link name="_wheel_RL">
    <inertial>
      <origin rpy="0 0 0" xyz="6.27955468179842E-09 -8.84368271322766E-09 -0.000243945799877326"/>
      <mass value="0.316802379932942"/>
      <inertia ixx="0.000185524613388858" ixy="-3.95566165674954E-11" ixz="1.17507787929333E-10" iyy="0.000185524592122908" iyz="9.32696147810741E-11" izz="0.000329541494439521"/>
    </inertial>
    <visual>
      <origin rpy="0 0 0" xyz="0 0 0"/>
      <geometry>
        <mesh filename="package://home_custom_base_description/meshes/visual/wheel.STL"/>
      </geometry>
      <material name="home_base_gray"/>
    </visual>
    <collision>
      <origin rpy="0 0 0" xyz="0 0 0"/>
      <geometry>
        <mesh filename="package://home_custom_base_description/meshes/visual/wheel.STL"/>
      </geometry>
    </collision>
  </link>
  <joint name="_wheel_RL_joint" type="continuous">
    <origin rpy="-1.5707963267949 0 0" xyz="-0.184790699909991 0.219394995052441 0.0376959841787652"/>
    <parent link="_base_link"/>
    <child link="_wheel_RL"/>
    <axis xyz="0 0 1"/>
  </joint>
  <!-- =================== wheel_RR =================== -->
  <link name="_wheel_RR">
    <inertial>
      <origin rpy="0 0 0" xyz="1.54742141322828E-09 1.26432938458987E-08 -0.000225751989580358"/>
      <mass value="0.316522156157189"/>
      <inertia ixx="0.000185501841998064" ixy="-9.89385955526853E-15" ixz="-2.625503122693E-11" iyy="0.00018550184097349" iyz="-2.87014788963402E-11" izz="0.000329540832766985"/>
    </inertial>
    <visual>
      <origin rpy="0 0 0" xyz="0 0 0"/>
      <geometry>
        <mesh filename="package://home_custom_base_description/meshes/visual/wheel.STL"/>
      </geometry>
      <material name="home_base_gray"/>
    </visual>
    <collision>
      <origin rpy="0 0 0" xyz="0 0 0"/>
      <geometry>
        <mesh filename="package://home_custom_base_description/meshes/visual/wheel.STL"/>
      </geometry>
    </collision>
  </link>
  <joint name="_wheel_RR_joint" type="continuous">
    <origin rpy="-1.5707963267949 0 0" xyz="-0.184790699909991 -0.219395004947559 0.0376959841787661"/>
    <parent link="_base_link"/>
    <child link="_wheel_RR"/>
    <axis xyz="0 0 1"/>
  </joint>
  <!-- =================== lidar_front =================== -->
  <link name="_lidar_front">
    <inertial>
      <origin rpy="0 0 0" xyz="-0.000159118177998852 3.36756577745678E-06 -0.00515345431268351"/>
      <mass value="0.100467493631956"/>
      <inertia ixx="3.42207960441524E-05" ixy="9.82554883966053E-09" ixz="-2.35749897825955E-07" iyy="3.47512781108353E-05" iyz="4.57302960893946E-09" izz="4.25510359877868E-05"/>
    </inertial>
    <visual>
      <origin rpy="0 0 0" xyz="0 0 0"/>
      <geometry>
        <mesh filename="package://home_custom_base_description/meshes/visual/lidar_front.STL"/>
      </geometry>
      <material name="home_base_lidar"/>
    </visual>
    <collision>
      <origin rpy="0 0 0" xyz="0 0 0"/>
      <geometry>
        <mesh filename="package://home_custom_base_description/meshes/visual/lidar_front.STL"/>
      </geometry>
    </collision>
  </link>
  <joint name="_lidar_front_joint" type="fixed">
    <origin rpy="0 0 -1.5707963267949" xyz="0.287749512711774 -0.207249957761446 0.135795984178765"/>
    <parent link="_base_link"/>
    <child link="_lidar_front"/>
  </joint>
  <!-- =================== lidar_rear =================== -->
  <link name="_lidar_rear">
    <inertial>
      <origin rpy="0 0 0" xyz="-0.000159118177998907 3.36756577740127E-06 -0.00515345431268352"/>
      <mass value="0.100467493631956"/>
      <inertia ixx="3.42207960441524E-05" ixy="9.8255488396398E-09" ixz="-2.35749897825974E-07" iyy="3.47512781108353E-05" iyz="4.57302960896798E-09" izz="4.25510359877867E-05"/>
    </inertial>
    <visual>
      <origin rpy="0 0 0" xyz="0 0 0"/>
      <geometry>
        <mesh filename="package://home_custom_base_description/meshes/visual/lidar_rear.STL"/>
      </geometry>
      <material name="home_base_lidar"/>
    </visual>
    <collision>
      <origin rpy="0 0 0" xyz="0 0 0"/>
      <geometry>
        <mesh filename="package://home_custom_base_description/meshes/visual/lidar_rear.STL"/>
      </geometry>
    </collision>
  </link>
  <joint name="_lidar_rear_joint" type="fixed">
    <origin rpy="0 0 1.5707963267949" xyz="-0.287749512711767 0.207249947866326 0.135795984178765"/>
    <parent link="_base_link"/>
    <child link="_lidar_rear"/>
  </joint>
  <link name="xarm_base"/>
  <joint name="xarm_joint" type="fixed">
    <origin rpy="0 0 0" xyz="0.0410000000000036 -0.00367166302995694 0.520695984178765"/>
    <parent link="_base_link"/>
    <child link="xarm_base"/>
    <axis xyz="0 0 0"/>
  </joint>
  <ros2_control name="home_base_hardware" type="system">
    <hardware>
      <plugin>gz_ros2_control/GazeboSimSystem</plugin>
    </hardware>
    <joint name="_wheel_FL_joint">
      <command_interface name="velocity">
        <param name="min">-10</param>
        <param name="max">10</param>
      </command_interface>
      <state_interface name="velocity"/>
      <state_interface name="position"/>
    </joint>
    <joint name="_wheel_FR_joint">
      <command_interface name="velocity">
        <param name="min">-10</param>
        <param name="max">10</param>
      </command_interface>
      <state_interface name="velocity"/>
      <state_interface name="position"/>
    </joint>
    <joint name="_wheel_RL_joint">
      <command_interface name="velocity">
        <param name="min">-10</param>
        <param name="max">10</param>
      </command_interface>
      <state_interface name="velocity"/>
      <state_interface name="position"/>
    </joint>
    <joint name="_wheel_RR_joint">
      <command_interface name="velocity">
        <param name="min">-10</param>
        <param name="max">10</param>
      </command_interface>
      <state_interface name="velocity"/>
      <state_interface name="position"/>
    </joint>
  </ros2_control>
  <!-- To emulate Mecanum wheels in Gazebo with spherical collisions it
  requires a custom friction model so the vehicle can strafe left to right -->
  <!-- Wheel friction properties -->
  <gazebo reference="_wheel_RL">
    <collision>
      <surface>
        <friction>
          <ode>
            <mu>1.0</mu>
            <mu2>0.0</mu2>
            <fdir1 gz:expressed_in="base_link">1 -1 0</fdir1>
          </ode>
        </friction>
      </surface>
    </collision>
  </gazebo>
  <gazebo reference="_wheel_RR">
    <collision>
      <surface>
        <friction>
          <ode>
            <mu>1.0</mu>
            <mu2>0.0</mu2>
            <fdir1 gz:expressed_in="base_link">1 -1 0</fdir1>
          </ode>
        </friction>
      </surface>
    </collision>
  </gazebo>
  <gazebo reference="_wheel_FL">
    <collision>
      <surface>
        <friction>
          <ode>
            <mu>1.0</mu>
            <mu2>0.0</mu2>
            <fdir1 gz:expressed_in="base_link">1 -1 0</fdir1>
          </ode>
        </friction>
      </surface>
    </collision>
  </gazebo>
  <gazebo reference="_wheel_FR">
    <collision>
      <surface>
        <friction>
          <ode>
            <mu>1.0</mu>
            <mu2>0.0</mu2>
            <fdir1 gz:expressed_in="base_link">1 -1 0</fdir1>
          </ode>
        </friction>
      </surface>
    </collision>
  </gazebo>
  <!-- Gazebo ROS2 Control Plugin -->
  <gazebo>
    <plugin filename="gz_ros2_control-system" name="gz_ros2_control::GazeboSimROS2ControlPlugin">
      <parameters>/home/jeremy/home2/install/home_custom_base_simulation/share/home_custom_base_simulation/config/ros2_control_mecanum.yaml</parameters>
      <ros>
        <robot_param>robot_description</robot_param>
        <robot_param_node>robot_state_publisher</robot_param_node>
      </ros>
    </plugin>
  </gazebo>
  <!-- Webots driver plugin configuration -->
  <webots>
    <plugin type="webots_ros2_control::Ros2Control"/>
  </webots>
  <!-- The world<->base_link offset matters for MoveIt because "world" is the
       planning frame: the plane-collision-object added by perception_3d in
       "base_link" gets stored by MoveIt in "world", and pick_server.check_
       feasibility compares its z against the grasp pose (in "base_link").
       Any non-zero offset becomes a silent frame mismatch that fails every
       pick.  On the real robot the 0.3 m pedestal is the physical mounting;
       in MuJoCo the arm is attached directly to world and there is no
       pedestal, so pin world<->base_link at identity for sim only. -->
  <link name="world"/>
  <joint name="world_to_base" type="fixed">
    <parent link="world"/>
    <child link="_base_footprint"/>
    <origin rpy="0 0 0" xyz="0 0 0.3"/>
  </joint>
  <!-- Insert at the beginning of xarm_device_macro.xacro -->
  <material name="Black">
    <color rgba="0.0 0.0 0.0 1.0"/>
  </material>
  <material name="Red">
    <color rgba="0.8 0.0 0.0 1.0"/>
  </material>
  <material name="White">
    <color rgba="1.0 1.0 1.0 1.0"/>
  </material>
  <material name="Silver">
    <color rgba="0.753 0.753 0.753 1.0"/>
  </material>
  <joint name="world_joint" type="fixed">
    <parent link="xarm_base"/>
    <child link="link_base"/>
    <origin rpy="0 0 0" xyz="0 0 0"/>
    <axis xyz="0 0 1"/>
  </joint>
  <ros2_control name="uf_robot_hardware/UFRobotSystemHardware" type="system">
    <hardware>
      <plugin>uf_robot_hardware/UFRobotSystemHardware</plugin>
      <param name="hw_ns">xarm</param>
      <param name="velocity_control">False</param>
      <param name="prefix">P</param>
      <param name="robot_ip">R</param>
      <param name="report_type">normal</param>
      <param name="dof">6</param>
      <param name="baud_checkset">True</param>
      <param name="default_gripper_baud">2000000</param>
      <param name="robot_type">xarm</param>
      <param name="add_gripper">False</param>
      <param name="add_bio_gripper">False</param>
      <!-- fake -->
      <!-- <plugin>fake_components/GenericSystem</plugin> -->
      <!-- gazebo -->
      <!-- <plugin>gazebo_ros2_control/GazeboSystem</plugin> -->
      <!-- real xarm -->
      <!-- <plugin>uf_robot_hardware/UFRobotSystemHardware</plugin> -->
    </hardware>
    <joint name="joint1">
      <command_interface name="position">
        <param name="min">-6.283185307179586</param>
        <param name="max">6.283185307179586</param>
      </command_interface>
      <command_interface name="velocity">
        <param name="min">-3.14</param>
        <param name="max">3.14</param>
      </command_interface>
      <state_interface name="position">
        <param name="initial_value">-1.5710340738296509</param>
      </state_interface>
      <state_interface name="velocity"/>
      <!-- <state_interface name="effort"/> -->
    </joint>
    <joint name="joint2">
      <command_interface name="position">
        <param name="min">-2.059</param>
        <param name="max">2.0944</param>
      </command_interface>
      <command_interface name="velocity">
        <param name="min">-3.14</param>
        <param name="max">3.14</param>
      </command_interface>
      <state_interface name="position">
        <param name="initial_value">-0.7855611443519592</param>
      </state_interface>
      <state_interface name="velocity"/>
      <!-- <state_interface name="effort"/> -->
    </joint>
    <joint name="joint3">
      <command_interface name="position">
        <param name="min">-3.927</param>
        <param name="max">0.19198</param>
      </command_interface>
      <command_interface name="velocity">
        <param name="min">-3.14</param>
        <param name="max">3.14</param>
      </command_interface>
      <state_interface name="position">
        <param name="initial_value">-1.5714118480682373</param>
      </state_interface>
      <state_interface name="velocity"/>
      <!-- <state_interface name="effort"/> -->
    </joint>
    <joint name="joint4">
      <command_interface name="position">
        <param name="min">-6.283185307179586</param>
        <param name="max">6.283185307179586</param>
      </command_interface>
      <command_interface name="velocity">
        <param name="min">-3.14</param>
        <param name="max">3.14</param>
      </command_interface>
      <state_interface name="position">
        <param name="initial_value">0.0</param>
      </state_interface>
      <state_interface name="velocity"/>
      <!-- <state_interface name="effort"/> -->
    </joint>
    <joint name="joint5">
      <command_interface name="position">
        <param name="min">-1.69297</param>
        <param name="max">3.141592653589793</param>
      </command_interface>
      <command_interface name="velocity">
        <param name="min">-3.14</param>
        <param name="max">3.14</param>
      </command_interface>
      <state_interface name="position">
        <param name="initial_value">0.87266463</param>
      </state_interface>
      <state_interface name="velocity"/>
      <!-- <state_interface name="effort"/> -->
    </joint>
    <joint name="joint6">
      <command_interface name="position">
        <param name="min">-6.283185307179586</param>
        <param name="max">6.283185307179586</param>
      </command_interface>
      <command_interface name="velocity">
        <param name="min">-3.14</param>
        <param name="max">3.14</param>
      </command_interface>
      <state_interface name="position">
        <param name="initial_value">0.785</param>
      </state_interface>
      <state_interface name="velocity"/>
      <!-- <state_interface name="effort"/> -->
    </joint>
  </ros2_control>
  <link name="link_base">
    <inertial>
      <origin rpy="0 0 0" xyz="0.0 0.0 0.09103"/>
      <mass value="2.7"/>
      <inertia ixx="0.00494875" ixy="-3.5E-06" ixz="1.25E-05" iyy="0.00494174" iyz="1.67E-06" izz="0.002219"/>
    </inertial>
    <visual>
      <geometry>
        <mesh filename="package://xarm_description/meshes/xarm6/visual/link_base.stl"/>
      </geometry>
      <origin rpy="0 0 0" xyz="0 0 0"/>
      <material name="White"/>
    </visual>
    <collision>
      <geometry>
        <mesh filename="package://xarm_description/meshes/xarm6/visual/link_base.stl"/>
      </geometry>
      <origin rpy="0 0 0" xyz="0 0 0"/>
    </collision>
  </link>
  <link name="link1">
    <inertial>
      <origin rpy="0 0 0" xyz="0.00022 0.02951 -0.0124"/>
      <mass value="2.3814"/>
      <inertia ixx="0.0058562" ixy="-1.79e-05" ixz="3.55e-06" iyy="0.0050316" iyz="-0.000888336" izz="0.003536652"/>
    </inertial>
    <visual>
      <geometry>
        <mesh filename="package://xarm_description/meshes/xarm6/visual/link1.stl"/>
      </geometry>
      <origin rpy="0 0 0" xyz="0 0 0"/>
      <material name="White"/>
    </visual>
    <collision>
      <geometry>
        <mesh filename="package://xarm_description/meshes/xarm6/visual/link1.stl"/>
      </geometry>
      <origin rpy="0 0 0" xyz="0 0 0"/>
    </collision>
  </link>
  <joint name="joint1" type="revolute">
    <parent link="link_base"/>
    <child link="link1"/>
    <origin rpy="0 0 0" xyz="0 0 0.267"/>
    <axis xyz="0 0 1"/>
    <limit effort="50.0" lower="-6.283185307179586" upper="6.283185307179586" velocity="3.14"/>
    <dynamics damping="1.0" friction="1.0"/>
  </joint>
  <link name="link2">
    <inertial>
      <origin rpy="0 0 0" xyz="0.03881 -0.22783 0.03496"/>
      <mass value="2.2675"/>
      <inertia ixx="0.028315776" ixy="0.005" ixz="0.00066546" iyy="0.0058" iyz="-0.0045741" izz="0.0273447"/>
    </inertial>
    <visual>
      <geometry>
        <mesh filename="package://xarm_description/meshes/xarm6/visual/link2.stl"/>
      </geometry>
      <origin rpy="0 0 0" xyz="0 0 0"/>
      <material name="White"/>
    </visual>
    <collision>
      <geometry>
        <mesh filename="package://xarm_description/meshes/xarm6/visual/link2.stl"/>
      </geometry>
      <origin rpy="0 0 0" xyz="0 0 0"/>
    </collision>
  </link>
  <joint name="joint2" type="revolute">
    <parent link="link1"/>
    <child link="link2"/>
    <origin rpy="-1.5708 0 0" xyz="0 0 0"/>
    <axis xyz="0 0 1"/>
    <limit effort="50.0" lower="-2.059" upper="2.0944" velocity="3.14"/>
    <dynamics damping="1.0" friction="1.0"/>
  </joint>
  <link name="link3">
    <inertial>
      <origin rpy="0 0 0" xyz="0.07041 0.11631 0.0107"/>
      <mass value="1.875"/>
      <inertia ixx="0.0063483" ixy="-0.0015397" ixz="0.00096858" iyy="0.00379758" iyz="0.00186567" izz="0.00595768"/>
    </inertial>
    <visual>
      <geometry>
        <mesh filename="package://xarm_description/meshes/xarm6/visual/link3.stl"/>
      </geometry>
      <origin rpy="0 0 0" xyz="0 0 0"/>
      <material name="White"/>
    </visual>
    <collision>
      <geometry>
        <mesh filename="package://xarm_description/meshes/xarm6/visual/link3.stl"/>
      </geometry>
      <origin rpy="0 0 0" xyz="0 0 0"/>
    </collision>
  </link>
  <joint name="joint3" type="revolute">
    <parent link="link2"/>
    <child link="link3"/>
    <origin rpy="0 0 0" xyz="0.0535 -0.2845 0"/>
    <axis xyz="0 0 1"/>
    <limit effort="32.0" lower="-3.927" upper="0.19198" velocity="3.14"/>
    <dynamics damping="1.0" friction="1.0"/>
  </joint>
  <link name="link4">
    <inertial>
      <origin rpy="0 0 0" xyz="-0.00018 0.01798 -0.02291"/>
      <mass value="1.3192"/>
      <inertia ixx="0.004896" ixy="-6.925e-06" ixz="-1.418e-05" iyy="0.00445694" iyz="-0.00023186" izz="0.00134332"/>
    </inertial>
    <visual>
      <geometry>
        <mesh filename="package://xarm_description/meshes/xarm6/visual/link4.stl"/>
      </geometry>
      <origin rpy="0 0 0" xyz="0 0 0"/>
      <material name="White"/>
    </visual>
    <collision>
      <geometry>
        <mesh filename="package://xarm_description/meshes/xarm6/visual/link4.stl"/>
      </geometry>
      <origin rpy="0 0 0" xyz="0 0 0"/>
    </collision>
  </link>
  <joint name="joint4" type="revolute">
    <parent link="link3"/>
    <child link="link4"/>
    <origin rpy="-1.5708 0 0" xyz="0.0775 0.3425 0"/>
    <axis xyz="0 0 1"/>
    <limit effort="32.0" lower="-6.283185307179586" upper="6.283185307179586" velocity="3.14"/>
    <dynamics damping="1.0" friction="1.0"/>
  </joint>
  <link name="link5">
    <inertial>
      <origin rpy="0 0 0" xyz="0.0651 0.03096 0.00315"/>
      <mass value="1.33854"/>
      <inertia ixx="0.00146378" ixy="-0.000450624" ixz="0.000284306" iyy="0.00184192" iyz="0.000130866" izz="0.002333524"/>
    </inertial>
    <visual>
      <geometry>
        <mesh filename="package://xarm_description/meshes/xarm6/visual/link5.stl"/>
      </geometry>
      <origin rpy="0 0 0" xyz="0 0 0"/>
      <material name="White"/>
    </visual>
    <collision>
      <geometry>
        <mesh filename="package://xarm_description/meshes/xarm6/visual/link5.stl"/>
      </geometry>
      <origin rpy="0 0 0" xyz="0 0 0"/>
    </collision>
  </link>
  <joint name="joint5" type="revolute">
    <parent link="link4"/>
    <child link="link5"/>
    <origin rpy="1.5708 0 0" xyz="0 0 0"/>
    <axis xyz="0 0 1"/>
    <limit effort="32.0" lower="-1.69297" upper="3.141592653589793" velocity="3.14"/>
    <dynamics damping="1.0" friction="1.0"/>
  </joint>
  <link name="link6">
    <inertial>
      <origin rpy="0 0 0" xyz="0 -0.00677 -0.01098"/>
      <mass value="0.17"/>
      <inertia ixx="9.3e-05" ixy="-0.0" ixz="-0.0" iyy="5.87e-05" iyz="-3.6e-06" izz="0.000132"/>
    </inertial>
    <visual>
      <geometry>
        <mesh filename="package://xarm_description/meshes/xarm6/visual/link6.stl"/>
      </geometry>
      <origin rpy="0 0 0" xyz="0 0 0"/>
      <material name="Silver"/>
    </visual>
    <collision>
      <geometry>
        <mesh filename="package://xarm_description/meshes/end_tool/collision/end_tool.stl"/>
      </geometry>
      <origin rpy="0 0 0" xyz="0 0 0"/>
    </collision>
  </link>
  <joint name="joint6" type="revolute">
    <parent link="link5"/>
    <child link="link6"/>
    <origin rpy="-1.5708 0 0" xyz="0.076 0.097 0"/>
    <axis xyz="0 0 1"/>
    <limit effort="20.0" lower="-6.283185307179586" upper="6.283185307179586" velocity="3.14"/>
    <dynamics damping="1.0" friction="1.0"/>
  </joint>
  <!-- <link name="${prefix}link_eef" />
    <joint name="${prefix}joint_eef" type="fixed">
      <origin xyz="0 0 0" rpy="0 0 0" />
      <parent link="${prefix}link6" />
      <child link="${prefix}link_eef" />
    </joint> -->
  <transmission name="tran1">
    <type>transmission_interface/SimpleTransmission</type>
    <joint name="joint1">
      <hardwareInterface>hardware_interface/PositionJointInterface</hardwareInterface>
    </joint>
    <actuator name="motor1">
      <hardwareInterface>hardware_interface/PositionJointInterface</hardwareInterface>
      <mechanicalReduction>100</mechanicalReduction>
    </actuator>
  </transmission>
  <transmission name="tran2">
    <type>transmission_interface/SimpleTransmission</type>
    <joint name="joint2">
      <hardwareInterface>hardware_interface/PositionJointInterface</hardwareInterface>
    </joint>
    <actuator name="motor2">
      <hardwareInterface>hardware_interface/PositionJointInterface</hardwareInterface>
      <mechanicalReduction>100</mechanicalReduction>
    </actuator>
  </transmission>
  <transmission name="tran3">
    <type>transmission_interface/SimpleTransmission</type>
    <joint name="joint3">
      <hardwareInterface>hardware_interface/PositionJointInterface</hardwareInterface>
    </joint>
    <actuator name="motor3">
      <hardwareInterface>hardware_interface/PositionJointInterface</hardwareInterface>
      <mechanicalReduction>100</mechanicalReduction>
    </actuator>
  </transmission>
  <transmission name="tran4">
    <type>transmission_interface/SimpleTransmission</type>
    <joint name="joint4">
      <hardwareInterface>hardware_interface/PositionJointInterface</hardwareInterface>
    </joint>
    <actuator name="motor4">
      <hardwareInterface>hardware_interface/PositionJointInterface</hardwareInterface>
      <mechanicalReduction>100</mechanicalReduction>
    </actuator>
  </transmission>
  <transmission name="tran5">
    <type>transmission_interface/SimpleTransmission</type>
    <joint name="joint5">
      <hardwareInterface>hardware_interface/PositionJointInterface</hardwareInterface>
    </joint>
    <actuator name="motor5">
      <hardwareInterface>hardware_interface/PositionJointInterface</hardwareInterface>
      <mechanicalReduction>100</mechanicalReduction>
    </actuator>
  </transmission>
  <transmission name="tran6">
    <type>transmission_interface/SimpleTransmission</type>
    <joint name="joint6">
      <hardwareInterface>hardware_interface/PositionJointInterface</hardwareInterface>
    </joint>
    <actuator name="motor6">
      <hardwareInterface>hardware_interface/PositionJointInterface</hardwareInterface>
      <mechanicalReduction>100</mechanicalReduction>
    </actuator>
  </transmission>
  <gazebo reference="link_base">
    <selfCollide>true</selfCollide>
  </gazebo>
  <gazebo reference="link1">
    <selfCollide>true</selfCollide>
  </gazebo>
  <gazebo reference="link2">
    <selfCollide>true</selfCollide>
  </gazebo>
  <gazebo reference="link3">
    <selfCollide>true</selfCollide>
  </gazebo>
  <gazebo reference="link4">
    <selfCollide>true</selfCollide>
  </gazebo>
  <gazebo reference="link5">
    <selfCollide>true</selfCollide>
  </gazebo>
  <gazebo reference="link6">
    <selfCollide>true</selfCollide>
  </gazebo>
  <link name="link_eef"/>
  <joint name="joint_eef" type="fixed">
    <origin rpy="0 0 0" xyz="0 0 0"/>
    <parent link="link6"/>
    <child link="link_eef"/>
    <axis xyz="0 0 1"/>
  </joint>
  <!-- Insert at the end of xarm_device_macro.xacro -->
  <!-- OLD GRIPPER    -->
  <!-- Gripper -->
  <!-- <xacro:include filename="$(find frida_description)/urdf/Gripper/Commercial/gripper.xacro" />
    <xacro:load_gripper attach_to="link_eef" xyz="0 0 0" rpy="2.3562 -1.5708 0" /> -->
  <!-- ZED MACRO -->
  <!-- <xacro:include filename="$(find frida_description)/urdf/zed/zed.xacro" />
  <xacro:load_zed attach_to="gripper" xyz="0.046461 0 -0.075649" rpy="0 0.81804 0" /> -->
  <joint name="gripper_grasp_joint" type="fixed">
    <parent link="link_eef"/>
    <child link="gripper_grasp_frame"/>
    <origin rpy="0 0 -0.7854" xyz="0 0 0"/>
  </joint>
  <link name="gripper_grasp_frame"> </link>
  <link name="zed"/>
  <joint name="ZED" type="fixed">
    <origin rpy="0 -0.7854 -1.5708" xyz="0 -0.095626 -0.005"/>
    <parent link="gripper"/>
    <child link="zed"/>
    <axis xyz="0 0 1"/>
  </joint>
  <joint name="gripper_fix" type="fixed">
    <parent link="link_eef"/>
    <child link="gripper"/>
    <origin rpy="0 0 3.926" xyz="0 0 0.046"/>
    <axis xyz="0 0 1"/>
  </joint>
  <link name="gripper">
    <inertial>
      <origin rpy="0 0 0" xyz="0.00033783 -0.0065249 0.0057345"/>
      <mass value="0.43538"/>
      <inertia ixx="0.00028883" ixy="-1.3378E-06" ixz="-7.8684E-07" iyy="0.0016861" iyz="-7.2811E-06" izz="0.0015525"/>
    </inertial>
    <visual>
      <origin rpy="0 0 0" xyz="0 0 0"/>
      <geometry>
        <mesh filename="file:///home/jeremy/home2/install/frida_description/share/frida_description/urdf/meshes/Gripper/Custom/gripper.STL"/>
      </geometry>
      <material name="">
        <color rgba="1 1 1 1"/>
      </material>
    </visual>
    <collision>
      <origin rpy="0 0 0" xyz="0 0 0"/>
      <geometry>
        <mesh filename="file:///home/jeremy/home2/install/frida_description/share/frida_description/urdf/meshes/Gripper/Custom/gripper.STL"/>
      </geometry>
    </collision>
  </link>
  <link name="right_finger">
    <inertial>
      <origin rpy="0 0 0" xyz="-0.0042467 -4.6842E-05 0.048292"/>
      <mass value="0.1028"/>
      <inertia ixx="8.1099e-05" ixy="3.8202e-08" ixz="1.9384e-06" iyy="7.2688e-05" iyz="-2.3121e-07" izz="1.8782e-05"/>
    </inertial>
    <visual>
      <origin rpy="0 0 0" xyz="0 0 0"/>
      <geometry>
        <mesh filename="file:///home/jeremy/home2/install/frida_description/share/frida_description/urdf/meshes/Gripper/Custom/right_finger.STL"/>
      </geometry>
      <material name="">
        <color rgba="1 1 1 1"/>
      </material>
    </visual>
    <collision>
      <origin rpy="0 0 0" xyz="0 0 0"/>
      <geometry>
        <mesh filename="file:///home/jeremy/home2/install/frida_description/share/frida_description/urdf/meshes/Gripper/Custom/right_finger.STL"/>
      </geometry>
    </collision>
  </link>
  <link name="left_finger">
    <inertial>
      <origin rpy="0 0 0" xyz="0.0042467 4.6842E-05 0.048292"/>
      <mass value="0.1028"/>
      <inertia ixx="8.1099e-05" ixy="3.8202e-08" ixz="-1.9384e-06" iyy="7.2688e-05" iyz="2.3121e-07" izz="1.8782e-05"/>
    </inertial>
    <visual>
      <origin rpy="0 0 0" xyz="0 0 0"/>
      <geometry>
        <mesh filename="file:///home/jeremy/home2/install/frida_description/share/frida_description/urdf/meshes/Gripper/Custom/left_finger.STL"/>
      </geometry>
      <material name="">
        <color rgba="1 1 1 1"/>
      </material>
    </visual>
    <collision>
      <origin rpy="0 0 0" xyz="0 0 0"/>
      <geometry>
        <mesh filename="file:///home/jeremy/home2/install/frida_description/share/frida_description/urdf/meshes/Gripper/Custom/left_finger.STL"/>
      </geometry>
    </collision>
  </link>
  <joint name="rightfinger" type="prismatic">
    <origin rpy="0 0 0" xyz="-0.069 0 0.017"/>
    <parent link="gripper"/>
    <child link="right_finger"/>
    <axis xyz="1 0 0"/>
    <limit effort="1" lower="0" upper="0.056" velocity="8"/>
    <!-- Damping replaces the removed kv on the MuJoCo position actuator;
         real-robot controllers ignore URDF joint dynamics so this stays
         sim-only in effect. -->
    <dynamics damping="5.0" friction="0.0"/>
  </joint>
  <joint name="leftfinger" type="prismatic">
    <origin rpy="0 0 0" xyz="0.069 0 0.017"/>
    <parent link="gripper"/>
    <child link="left_finger"/>
    <axis xyz="-1 0 0"/>
    <limit effort="1" lower="0" upper="0.056" velocity="8"/>
    <mimic joint="rightfinger" multiplier="1" offset="0"/>
  </joint>
  <joint name="zed" type="fixed">
    <parent link="zed"/>
    <child link="zed_camera_link"/>
    <origin rpy="0 0 0" xyz="0.0 0 0.0"/>
  </joint>
  <link name="zed_camera_link">
    <inertial>
      <origin rpy="0 0 0" xyz="0.00022189 -2.7346E-06 1.8693E-05"/>
      <mass value="0.230"/>
      <inertia ixx="0.00038053" ixy="2.1426E-09" ixz="-8.1327E-08" iyy="2.3258E-05" iyz="6.6645E-09" izz="0.00038297"/>
    </inertial>
    <visual>
      <origin rpy="0 0 0" xyz="0 0 0"/>
      <geometry>
        <mesh filename="file:///home/jeremy/home2/install/frida_description/share/frida_description/urdf/meshes/Gripper/Commercial/ZED.STL"/>
      </geometry>
      <material name="">
        <color rgba="0.102 0.102 0.102 1"/>
      </material>
    </visual>
    <collision>
      <origin rpy="0 0 0" xyz="0 0 0"/>
      <geometry>
        <mesh filename="file:///home/jeremy/home2/install/frida_description/share/frida_description/urdf/meshes/Gripper/Commercial/ZED.STL"/>
      </geometry>
    </collision>
  </link>
  <!-- <joint name="base_footprint_joint" type="fixed">
      <origin xyz="0 0 ${base_length/2 + caster_radius*2}" rpy="0 0 0" />        
      <parent link="base_footprint"/>
      <child link="base_link" />
    </joint> -->
</robot>
