<?xml version="1.0" ?>
<!-- =================================================================================== -->
<!-- |    This document was autogenerated by xacro from robot_description/frida_description/urdf/TMR2025/FRIDA_Real.urdf.xacro | -->
<!-- |    EDITING THIS FILE BY HAND IS NOT RECOMMENDED                                 | -->
<!-- =================================================================================== -->
<robot name="FRIDA" xmlns:gz="http://gazebosim.org/schema">
  <link name="base_link">
    <inertial>
      <origin rpy="0 0 0" xyz="0.031681 -0.0052694 0.10165"/>
      <mass value="200.075"/>
      <inertia ixx="0.44959" ixy="-0.005113" ixz="0.017804" iyy="0.46194" iyz="-0.00061969" izz="0.78515"/>
    </inertial>
    <visual>
      <origin rpy="0 0 0" xyz="0 0 0"/>
      <geometry>
        <mesh filename="file:///home/jeremy/home2/install/frida_description/share/frida_description/urdf/meshes/TMR2025/base_link.STL"/>
      </geometry>
      <material name="">
        <color rgba="0.745 0.203 0.482 1"/>
      </material>
    </visual>
    <collision>
      <origin rpy="0 0 0" xyz="0 0 0"/>
      <geometry>
        <mesh filename="file:///home/jeremy/home2/install/frida_description/share/frida_description/urdf/meshes/TMR2025/base_link_collision.stl"/>
      </geometry>
    </collision>
  </link>
  <link name="base_footprint"/>
  <joint name="base_footprint_joint" type="fixed">
    <parent link="base_link"/>
    <child link="base_footprint"/>
    <origin rpy="0 0 0 " xyz="0 0 0"/>
    <axis xyz="0 0 1"/>
  </joint>
  <link name="xarm_base"/>
  <joint name="xarm_base_joint" type="fixed">
    <origin rpy="0 0 1.57" xyz="0.036105613000001 0 0.441000000000001"/>
    <parent link="base_link"/>
    <child link="xarm_base"/>
    <axis xyz="0 0 1"/>
  </joint>
  <link name="laser">
    <inertial>
      <origin rpy="0 0 0" xyz="-1.3878E-17 3.3818E-34 -0.0125"/>
      <mass value="0.096211"/>
      <inertia ixx="3.4476E-05" ixy="-1.3255E-52" ixz="6.0099E-37" iyy="3.4476E-05" iyz="8.1342E-38" izz="5.8929E-05"/>
    </inertial>
    <visual>
      <origin rpy="0 0 0" xyz="0 0 0"/>
      <geometry>
        <mesh filename="file:///home/jeremy/home2/install/frida_description/share/frida_description/urdf/meshes/TMR2025/LIDAR.STL"/>
      </geometry>
      <material name="">
        <color rgba="0.102 0.102 0.102 1"/>
      </material>
    </visual>
    <collision>
      <origin rpy="0 0 0" xyz="0 0 0"/>
      <geometry>
        <mesh filename="file:///home/jeremy/home2/install/frida_description/share/frida_description/urdf/meshes/TMR2025/LIDAR.STL"/>
      </geometry>
    </collision>
  </link>
  <joint name="lidar" type="fixed">
    <origin rpy="0 0 3.14" xyz="0.16 0 0.002"/>
    <parent link="base_link"/>
    <child link="laser"/>
    <axis xyz="0 0 1"/>
  </joint>
  <link name="imu_base">
    <inertial>
      <origin rpy="0 0 0" xyz="-1.3878E-17 3.3818E-34 -0.0125"/>
      <mass value="0.096211"/>
      <inertia ixx="3.4476E-05" ixy="-1.3255E-52" ixz="6.0099E-37" iyy="3.4476E-05" iyz="8.1342E-38" izz="5.8929E-05"/>
    </inertial>
    <visual>
      <origin rpy="0 0 0" xyz="0 0 0"/>
      <material name="">
        <color rgba="0.102 0.102 0.102 1"/>
      </material>
      <geometry>
        <box size="0.01 0.01 0.01"/>
      </geometry>
    </visual>
    <collision>
      <origin rpy="0 0 0" xyz="0 0 0"/>
      <geometry>
        <box size="0.001 0.001 0.001"/>
      </geometry>
    </collision>
  </link>
  <joint name="imu_base_joint" type="fixed">
    <origin rpy="3.1416 3.1416 1.57" xyz="0.15026 0 0.002"/>
    <parent link="base_link"/>
    <child link="imu_base"/>
    <axis xyz="0 0 1"/>
  </joint>
  <link name="intel_realsense">
    <inertial>
      <origin rpy="0 0 0" xyz="-0.000276500325472787 -3.68172093455318E-07 -6.47494519674385E-05"/>
      <mass value="0.048201"/>
      <inertia ixx="2.7391E-05" ixy="-4.2599E-07" ixz="5.14365274506557E-08" iyy="3.3506E-06" iyz="-2.32499967543505E-08" izz="2.6652E-05"/>
    </inertial>
    <visual>
      <origin rpy="0 0 0" xyz="0 0 0"/>
      <geometry>
        <mesh filename="file:///home/jeremy/home2/install/frida_description/share/frida_description/urdf/meshes/TMR2025/intel_realsense.STL"/>
      </geometry>
      <material name="">
        <color rgba="0.776 0.757 0.737 1"/>
      </material>
    </visual>
    <collision>
      <origin rpy="0 0 0" xyz="0 0 0"/>
      <geometry>
        <mesh filename="file:///home/jeremy/home2/install/frida_description/share/frida_description/urdf/meshes/TMR2025/intel_realsense.STL"/>
      </geometry>
    </collision>
  </link>
  <joint name="intelrealsense" type="fixed">
    <origin rpy="0 0 0" xyz="0.140953490988428 0 0.428947355746093"/>
    <parent link="base_link"/>
    <child link="intel_realsense"/>
    <axis xyz="0 0 1"/>
  </joint>
  <!-- The world<->base_link offset matters for MoveIt because "world" is the
       planning frame: the plane-collision-object added by perception_3d in
       "base_link" gets stored by MoveIt in "world", and pick_server.check_
       feasibility compares its z against the grasp pose (in "base_link").
       Any non-zero offset becomes a silent frame mismatch that fails every
       pick.  On the real robot the 0.3 m pedestal is the physical mounting;
       in MuJoCo the arm is attached directly to world and there is no
       pedestal, so pin world<->base_link at identity for sim only. -->
  <link name="world"/>
  <joint name="world_to_base" type="fixed">
    <parent link="world"/>
    <child link="base_link"/>
    <origin rpy="0 0 0" xyz="0 0 0.3"/>
  </joint>
  <!-- Insert at the beginning of xarm_device_macro.xacro -->
  <material name="Black">
    <color rgba="0.0 0.0 0.0 1.0"/>
  </material>
  <material name="Red">
    <color rgba="0.8 0.0 0.0 1.0"/>
  </material>
  <material name="White">
    <color rgba="1.0 1.0 1.0 1.0"/>
  </material>
  <material name="Silver">
    <color rgba="0.753 0.753 0.753 1.0"/>
  </material>
  <joint name="world_joint" type="fixed">
    <parent link="xarm_base"/>
    <child link="link_base"/>
    <origin rpy="0 0 0" xyz="0 0 0"/>
    <axis xyz="0 0 1"/>
  </joint>
  <ros2_control name="uf_robot_hardware/UFRobotSystemHardware" type="system">
    <hardware>
      <plugin>uf_robot_hardware/UFRobotSystemHardware</plugin>
      <param name="hw_ns">xarm</param>
      <param name="velocity_control">False</param>
      <param name="prefix">P</param>
      <param name="robot_ip">R</param>
      <param name="report_type">normal</param>
      <param name="dof">6</param>
      <param name="baud_checkset">True</param>
      <param name="default_gripper_baud">2000000</param>
      <param name="robot_type">xarm</param>
      <param name="add_gripper">False</param>
      <param name="add_bio_gripper">False</param>
      <!-- fake -->
      <!-- <plugin>fake_components/GenericSystem</plugin> -->
      <!-- gazebo -->
      <!-- <plugin>gazebo_ros2_control/GazeboSystem</plugin> -->
      <!-- real xarm -->
      <!-- <plugin>uf_robot_hardware/UFRobotSystemHardware</plugin> -->
    </hardware>
    <joint name="joint1">
      <command_interface name="position">
        <param name="min">-6.283185307179586</param>
        <param name="max">6.283185307179586</param>
      </command_interface>
      <command_interface name="velocity">
        <param name="min">-3.14</param>
        <param name="max">3.14</param>
      </command_interface>
      <state_interface name="position">
        <param name="initial_value">-1.5710340738296509</param>
      </state_interface>
      <state_interface name="velocity"/>
      <!-- <state_interface name="effort"/> -->
    </joint>
    <joint name="joint2">
      <command_interface name="position">
        <param name="min">-2.059</param>
        <param name="max">2.0944</param>
      </command_interface>
      <command_interface name="velocity">
        <param name="min">-3.14</param>
        <param name="max">3.14</param>
      </command_interface>
      <state_interface name="position">
        <param name="initial_value">-0.7855611443519592</param>
      </state_interface>
      <state_interface name="velocity"/>
      <!-- <state_interface name="effort"/> -->
    </joint>
    <joint name="joint3">
      <command_interface name="position">
        <param name="min">-3.927</param>
        <param name="max">0.19198</param>
      </command_interface>
      <command_interface name="velocity">
        <param name="min">-3.14</param>
        <param name="max">3.14</param>
      </command_interface>
      <state_interface name="position">
        <param name="initial_value">-1.5714118480682373</param>
      </state_interface>
      <state_interface name="velocity"/>
      <!-- <state_interface name="effort"/> -->
    </joint>
    <joint name="joint4">
      <command_interface name="position">
        <param name="min">-6.283185307179586</param>
        <param name="max">6.283185307179586</param>
      </command_interface>
      <command_interface name="velocity">
        <param name="min">-3.14</param>
        <param name="max">3.14</param>
      </command_interface>
      <state_interface name="position">
        <param name="initial_value">0.0</param>
      </state_interface>
      <state_interface name="velocity"/>
      <!-- <state_interface name="effort"/> -->
    </joint>
    <joint name="joint5">
      <command_interface name="position">
        <param name="min">-1.69297</param>
        <param name="max">3.141592653589793</param>
      </command_interface>
      <command_interface name="velocity">
        <param name="min">-3.14</param>
        <param name="max">3.14</param>
      </command_interface>
      <state_interface name="position">
        <param name="initial_value">0.87266463</param>
      </state_interface>
      <state_interface name="velocity"/>
      <!-- <state_interface name="effort"/> -->
    </joint>
    <joint name="joint6">
      <command_interface name="position">
        <param name="min">-6.283185307179586</param>
        <param name="max">6.283185307179586</param>
      </command_interface>
      <command_interface name="velocity">
        <param name="min">-3.14</param>
        <param name="max">3.14</param>
      </command_interface>
      <state_interface name="position">
        <param name="initial_value">0.785</param>
      </state_interface>
      <state_interface name="velocity"/>
      <!-- <state_interface name="effort"/> -->
    </joint>
  </ros2_control>
  <link name="link_base">
    <inertial>
      <origin rpy="0 0 0" xyz="0.0 0.0 0.09103"/>
      <mass value="2.7"/>
      <inertia ixx="0.00494875" ixy="-3.5E-06" ixz="1.25E-05" iyy="0.00494174" iyz="1.67E-06" izz="0.002219"/>
    </inertial>
    <visual>
      <geometry>
        <mesh filename="package://xarm_description/meshes/xarm6/visual/link_base.stl"/>
      </geometry>
      <origin rpy="0 0 0" xyz="0 0 0"/>
      <material name="White"/>
    </visual>
    <collision>
      <geometry>
        <mesh filename="package://xarm_description/meshes/xarm6/visual/link_base.stl"/>
      </geometry>
      <origin rpy="0 0 0" xyz="0 0 0"/>
    </collision>
  </link>
  <link name="link1">
    <inertial>
      <origin rpy="0 0 0" xyz="0.00022 0.02951 -0.0124"/>
      <mass value="2.3814"/>
      <inertia ixx="0.0058562" ixy="-1.79e-05" ixz="3.55e-06" iyy="0.0050316" iyz="-0.000888336" izz="0.003536652"/>
    </inertial>
    <visual>
      <geometry>
        <mesh filename="package://xarm_description/meshes/xarm6/visual/link1.stl"/>
      </geometry>
      <origin rpy="0 0 0" xyz="0 0 0"/>
      <material name="White"/>
    </visual>
    <collision>
      <geometry>
        <mesh filename="package://xarm_description/meshes/xarm6/visual/link1.stl"/>
      </geometry>
      <origin rpy="0 0 0" xyz="0 0 0"/>
    </collision>
  </link>
  <joint name="joint1" type="revolute">
    <parent link="link_base"/>
    <child link="link1"/>
    <origin rpy="0 0 0" xyz="0 0 0.267"/>
    <axis xyz="0 0 1"/>
    <limit effort="50.0" lower="-6.283185307179586" upper="6.283185307179586" velocity="3.14"/>
    <dynamics damping="1.0" friction="1.0"/>
  </joint>
  <link name="link2">
    <inertial>
      <origin rpy="0 0 0" xyz="0.03881 -0.22783 0.03496"/>
      <mass value="2.2675"/>
      <inertia ixx="0.028315776" ixy="0.005" ixz="0.00066546" iyy="0.0058" iyz="-0.0045741" izz="0.0273447"/>
    </inertial>
    <visual>
      <geometry>
        <mesh filename="package://xarm_description/meshes/xarm6/visual/link2.stl"/>
      </geometry>
      <origin rpy="0 0 0" xyz="0 0 0"/>
      <material name="White"/>
    </visual>
    <collision>
      <geometry>
        <mesh filename="package://xarm_description/meshes/xarm6/visual/link2.stl"/>
      </geometry>
      <origin rpy="0 0 0" xyz="0 0 0"/>
    </collision>
  </link>
  <joint name="joint2" type="revolute">
    <parent link="link1"/>
    <child link="link2"/>
    <origin rpy="-1.5708 0 0" xyz="0 0 0"/>
    <axis xyz="0 0 1"/>
    <limit effort="50.0" lower="-2.059" upper="2.0944" velocity="3.14"/>
    <dynamics damping="1.0" friction="1.0"/>
  </joint>
  <link name="link3">
    <inertial>
      <origin rpy="0 0 0" xyz="0.07041 0.11631 0.0107"/>
      <mass value="1.875"/>
      <inertia ixx="0.0063483" ixy="-0.0015397" ixz="0.00096858" iyy="0.00379758" iyz="0.00186567" izz="0.00595768"/>
    </inertial>
    <visual>
      <geometry>
        <mesh filename="package://xarm_description/meshes/xarm6/visual/link3.stl"/>
      </geometry>
      <origin rpy="0 0 0" xyz="0 0 0"/>
      <material name="White"/>
    </visual>
    <collision>
      <geometry>
        <mesh filename="package://xarm_description/meshes/xarm6/visual/link3.stl"/>
      </geometry>
      <origin rpy="0 0 0" xyz="0 0 0"/>
    </collision>
  </link>
  <joint name="joint3" type="revolute">
    <parent link="link2"/>
    <child link="link3"/>
    <origin rpy="0 0 0" xyz="0.0535 -0.2845 0"/>
    <axis xyz="0 0 1"/>
    <limit effort="32.0" lower="-3.927" upper="0.19198" velocity="3.14"/>
    <dynamics damping="1.0" friction="1.0"/>
  </joint>
  <link name="link4">
    <inertial>
      <origin rpy="0 0 0" xyz="-0.00018 0.01798 -0.02291"/>
      <mass value="1.3192"/>
      <inertia ixx="0.004896" ixy="-6.925e-06" ixz="-1.418e-05" iyy="0.00445694" iyz="-0.00023186" izz="0.00134332"/>
    </inertial>
    <visual>
      <geometry>
        <mesh filename="package://xarm_description/meshes/xarm6/visual/link4.stl"/>
      </geometry>
      <origin rpy="0 0 0" xyz="0 0 0"/>
      <material name="White"/>
    </visual>
    <collision>
      <geometry>
        <mesh filename="package://xarm_description/meshes/xarm6/visual/link4.stl"/>
      </geometry>
      <origin rpy="0 0 0" xyz="0 0 0"/>
    </collision>
  </link>
  <joint name="joint4" type="revolute">
    <parent link="link3"/>
    <child link="link4"/>
    <origin rpy="-1.5708 0 0" xyz="0.0775 0.3425 0"/>
    <axis xyz="0 0 1"/>
    <limit effort="32.0" lower="-6.283185307179586" upper="6.283185307179586" velocity="3.14"/>
    <dynamics damping="1.0" friction="1.0"/>
  </joint>
  <link name="link5">
    <inertial>
      <origin rpy="0 0 0" xyz="0.0651 0.03096 0.00315"/>
      <mass value="1.33854"/>
      <inertia ixx="0.00146378" ixy="-0.000450624" ixz="0.000284306" iyy="0.00184192" iyz="0.000130866" izz="0.002333524"/>
    </inertial>
    <visual>
      <geometry>
        <mesh filename="package://xarm_description/meshes/xarm6/visual/link5.stl"/>
      </geometry>
      <origin rpy="0 0 0" xyz="0 0 0"/>
      <material name="White"/>
    </visual>
    <collision>
      <geometry>
        <mesh filename="package://xarm_description/meshes/xarm6/visual/link5.stl"/>
      </geometry>
      <origin rpy="0 0 0" xyz="0 0 0"/>
    </collision>
  </link>
  <joint name="joint5" type="revolute">
    <parent link="link4"/>
    <child link="link5"/>
    <origin rpy="1.5708 0 0" xyz="0 0 0"/>
    <axis xyz="0 0 1"/>
    <limit effort="32.0" lower="-1.69297" upper="3.141592653589793" velocity="3.14"/>
    <dynamics damping="1.0" friction="1.0"/>
  </joint>
  <link name="link6">
    <inertial>
      <origin rpy="0 0 0" xyz="0 -0.00677 -0.01098"/>
      <mass value="0.17"/>
      <inertia ixx="9.3e-05" ixy="-0.0" ixz="-0.0" iyy="5.87e-05" iyz="-3.6e-06" izz="0.000132"/>
    </inertial>
    <visual>
      <geometry>
        <mesh filename="package://xarm_description/meshes/xarm6/visual/link6.stl"/>
      </geometry>
      <origin rpy="0 0 0" xyz="0 0 0"/>
      <material name="Silver"/>
    </visual>
    <collision>
      <geometry>
        <mesh filename="package://xarm_description/meshes/end_tool/collision/end_tool.stl"/>
      </geometry>
      <origin rpy="0 0 0" xyz="0 0 0"/>
    </collision>
  </link>
  <joint name="joint6" type="revolute">
    <parent link="link5"/>
    <child link="link6"/>
    <origin rpy="-1.5708 0 0" xyz="0.076 0.097 0"/>
    <axis xyz="0 0 1"/>
    <limit effort="20.0" lower="-6.283185307179586" upper="6.283185307179586" velocity="3.14"/>
    <dynamics damping="1.0" friction="1.0"/>
  </joint>
  <!-- <link name="${prefix}link_eef" />
    <joint name="${prefix}joint_eef" type="fixed">
      <origin xyz="0 0 0" rpy="0 0 0" />
      <parent link="${prefix}link6" />
      <child link="${prefix}link_eef" />
    </joint> -->
  <transmission name="tran1">
    <type>transmission_interface/SimpleTransmission</type>
    <joint name="joint1">
      <hardwareInterface>hardware_interface/PositionJointInterface</hardwareInterface>
    </joint>
    <actuator name="motor1">
      <hardwareInterface>hardware_interface/PositionJointInterface</hardwareInterface>
      <mechanicalReduction>100</mechanicalReduction>
    </actuator>
  </transmission>
  <transmission name="tran2">
    <type>transmission_interface/SimpleTransmission</type>
    <joint name="joint2">
      <hardwareInterface>hardware_interface/PositionJointInterface</hardwareInterface>
    </joint>
    <actuator name="motor2">
      <hardwareInterface>hardware_interface/PositionJointInterface</hardwareInterface>
      <mechanicalReduction>100</mechanicalReduction>
    </actuator>
  </transmission>
  <transmission name="tran3">
    <type>transmission_interface/SimpleTransmission</type>
    <joint name="joint3">
      <hardwareInterface>hardware_interface/PositionJointInterface</hardwareInterface>
    </joint>
    <actuator name="motor3">
      <hardwareInterface>hardware_interface/PositionJointInterface</hardwareInterface>
      <mechanicalReduction>100</mechanicalReduction>
    </actuator>
  </transmission>
  <transmission name="tran4">
    <type>transmission_interface/SimpleTransmission</type>
    <joint name="joint4">
      <hardwareInterface>hardware_interface/PositionJointInterface</hardwareInterface>
    </joint>
    <actuator name="motor4">
      <hardwareInterface>hardware_interface/PositionJointInterface</hardwareInterface>
      <mechanicalReduction>100</mechanicalReduction>
    </actuator>
  </transmission>
  <transmission name="tran5">
    <type>transmission_interface/SimpleTransmission</type>
    <joint name="joint5">
      <hardwareInterface>hardware_interface/PositionJointInterface</hardwareInterface>
    </joint>
    <actuator name="motor5">
      <hardwareInterface>hardware_interface/PositionJointInterface</hardwareInterface>
      <mechanicalReduction>100</mechanicalReduction>
    </actuator>
  </transmission>
  <transmission name="tran6">
    <type>transmission_interface/SimpleTransmission</type>
    <joint name="joint6">
      <hardwareInterface>hardware_interface/PositionJointInterface</hardwareInterface>
    </joint>
    <actuator name="motor6">
      <hardwareInterface>hardware_interface/PositionJointInterface</hardwareInterface>
      <mechanicalReduction>100</mechanicalReduction>
    </actuator>
  </transmission>
  <gazebo reference="link_base">
    <selfCollide>true</selfCollide>
  </gazebo>
  <gazebo reference="link1">
    <selfCollide>true</selfCollide>
  </gazebo>
  <gazebo reference="link2">
    <selfCollide>true</selfCollide>
  </gazebo>
  <gazebo reference="link3">
    <selfCollide>true</selfCollide>
  </gazebo>
  <gazebo reference="link4">
    <selfCollide>true</selfCollide>
  </gazebo>
  <gazebo reference="link5">
    <selfCollide>true</selfCollide>
  </gazebo>
  <gazebo reference="link6">
    <selfCollide>true</selfCollide>
  </gazebo>
  <link name="link_eef"/>
  <joint name="joint_eef" type="fixed">
    <origin rpy="0 0 0" xyz="0 0 0"/>
    <parent link="link6"/>
    <child link="link_eef"/>
    <axis xyz="0 0 1"/>
  </joint>
  <!-- Insert at the end of xarm_device_macro.xacro -->
  <!-- OLD GRIPPER    -->
  <!-- Gripper -->
  <!-- <xacro:include filename="$(find frida_description)/urdf/Gripper/Commercial/gripper.xacro" />
    <xacro:load_gripper attach_to="link_eef" xyz="0 0 0" rpy="2.3562 -1.5708 0" /> -->
  <!-- ZED MACRO -->
  <!-- <xacro:include filename="$(find frida_description)/urdf/zed/zed.xacro" />
  <xacro:load_zed attach_to="gripper" xyz="0.046461 0 -0.075649" rpy="0 0.81804 0" /> -->
  <joint name="gripper_grasp_joint" type="fixed">
    <parent link="link_eef"/>
    <child link="gripper_grasp_frame"/>
    <origin rpy="0 0 -0.7854" xyz="0 0 0"/>
  </joint>
  <link name="gripper_grasp_frame"> </link>
  <link name="zed"/>
  <joint name="ZED" type="fixed">
    <origin rpy="0 -0.7854 -1.5708" xyz="0 -0.095626 -0.005"/>
    <parent link="gripper"/>
    <child link="zed"/>
    <axis xyz="0 0 1"/>
  </joint>
  <joint name="gripper_fix" type="fixed">
    <parent link="link_eef"/>
    <child link="gripper"/>
    <origin rpy="0 0 3.926" xyz="0 0 0.046"/>
    <axis xyz="0 0 1"/>
  </joint>
  <link name="gripper">
    <inertial>
      <origin rpy="0 0 0" xyz="0.00033783 -0.0065249 0.0057345"/>
      <mass value="0.43538"/>
      <inertia ixx="0.00028883" ixy="-1.3378E-06" ixz="-7.8684E-07" iyy="0.0016861" iyz="-7.2811E-06" izz="0.0015525"/>
    </inertial>
    <visual>
      <origin rpy="0 0 0" xyz="0 0 0"/>
      <geometry>
        <mesh filename="file:///home/jeremy/home2/install/frida_description/share/frida_description/urdf/meshes/Gripper/Custom/gripper.STL"/>
      </geometry>
      <material name="">
        <color rgba="1 1 1 1"/>
      </material>
    </visual>
    <collision>
      <origin rpy="0 0 0" xyz="0 0 0"/>
      <geometry>
        <mesh filename="file:///home/jeremy/home2/install/frida_description/share/frida_description/urdf/meshes/Gripper/Custom/gripper.STL"/>
      </geometry>
    </collision>
  </link>
  <link name="right_finger">
    <inertial>
      <origin rpy="0 0 0" xyz="-0.0042467 -4.6842E-05 0.048292"/>
      <mass value="0.1028"/>
      <inertia ixx="8.1099e-05" ixy="3.8202e-08" ixz="1.9384e-06" iyy="7.2688e-05" iyz="-2.3121e-07" izz="1.8782e-05"/>
    </inertial>
    <visual>
      <origin rpy="0 0 0" xyz="0 0 0"/>
      <geometry>
        <mesh filename="file:///home/jeremy/home2/install/frida_description/share/frida_description/urdf/meshes/Gripper/Custom/right_finger.STL"/>
      </geometry>
      <material name="">
        <color rgba="1 1 1 1"/>
      </material>
    </visual>
    <collision>
      <origin rpy="0 0 0" xyz="0 0 0"/>
      <geometry>
        <mesh filename="file:///home/jeremy/home2/install/frida_description/share/frida_description/urdf/meshes/Gripper/Custom/right_finger.STL"/>
      </geometry>
    </collision>
  </link>
  <link name="left_finger">
    <inertial>
      <origin rpy="0 0 0" xyz="0.0042467 4.6842E-05 0.048292"/>
      <mass value="0.1028"/>
      <inertia ixx="8.1099e-05" ixy="3.8202e-08" ixz="-1.9384e-06" iyy="7.2688e-05" iyz="2.3121e-07" izz="1.8782e-05"/>
    </inertial>
    <visual>
      <origin rpy="0 0 0" xyz="0 0 0"/>
      <geometry>
        <mesh filename="file:///home/jeremy/home2/install/frida_description/share/frida_description/urdf/meshes/Gripper/Custom/left_finger.STL"/>
      </geometry>
      <material name="">
        <color rgba="1 1 1 1"/>
      </material>
    </visual>
    <collision>
      <origin rpy="0 0 0" xyz="0 0 0"/>
      <geometry>
        <mesh filename="file:///home/jeremy/home2/install/frida_description/share/frida_description/urdf/meshes/Gripper/Custom/left_finger.STL"/>
      </geometry>
    </collision>
  </link>
  <joint name="rightfinger" type="prismatic">
    <origin rpy="0 0 0" xyz="-0.069 0 0.017"/>
    <parent link="gripper"/>
    <child link="right_finger"/>
    <axis xyz="1 0 0"/>
    <limit effort="1" lower="0" upper="0.056" velocity="8"/>
    <!-- Damping replaces the removed kv on the MuJoCo position actuator;
         real-robot controllers ignore URDF joint dynamics so this stays
         sim-only in effect. -->
    <dynamics damping="5.0" friction="0.0"/>
  </joint>
  <joint name="leftfinger" type="prismatic">
    <origin rpy="0 0 0" xyz="0.069 0 0.017"/>
    <parent link="gripper"/>
    <child link="left_finger"/>
    <axis xyz="-1 0 0"/>
    <limit effort="1" lower="0" upper="0.056" velocity="8"/>
    <mimic joint="rightfinger" multiplier="1" offset="0"/>
  </joint>
  <joint name="zed" type="fixed">
    <parent link="zed"/>
    <child link="zed_camera_link"/>
    <origin rpy="0 0 0" xyz="0.0 0 0.0"/>
  </joint>
  <link name="zed_camera_link">
    <inertial>
      <origin rpy="0 0 0" xyz="0.00022189 -2.7346E-06 1.8693E-05"/>
      <mass value="0.230"/>
      <inertia ixx="0.00038053" ixy="2.1426E-09" ixz="-8.1327E-08" iyy="2.3258E-05" iyz="6.6645E-09" izz="0.00038297"/>
    </inertial>
    <visual>
      <origin rpy="0 0 0" xyz="0 0 0"/>
      <geometry>
        <mesh filename="file:///home/jeremy/home2/install/frida_description/share/frida_description/urdf/meshes/Gripper/Commercial/ZED.STL"/>
      </geometry>
      <material name="">
        <color rgba="0.102 0.102 0.102 1"/>
      </material>
    </visual>
    <collision>
      <origin rpy="0 0 0" xyz="0 0 0"/>
      <geometry>
        <mesh filename="file:///home/jeremy/home2/install/frida_description/share/frida_description/urdf/meshes/Gripper/Commercial/ZED.STL"/>
      </geometry>
    </collision>
  </link>
  <!-- <joint name="base_footprint_joint" type="fixed">
      <origin xyz="0 0 ${base_length/2 + caster_radius*2}" rpy="0 0 0" />        
      <parent link="base_footprint"/>
      <child link="base_link" />
    </joint> -->
</robot>
