<?xml version="1.0" ?>
<!-- =================================================================================== -->
<!-- |    This document was autogenerated by xacro from /home/alegonzcamilla/roborregos_repos/home2/src/robot_description/frida_description/urdf/TMR2025/FRIDA_Real.urdf.xacro | -->
<!-- |    EDITING THIS FILE BY HAND IS NOT RECOMMENDED                                 | -->
<!-- =================================================================================== -->

<robot name="FRIDA">

  <link name="base_link">
    <inertial>
      <origin rpy="0 0 0" xyz="0.031681 -0.0052694 0.10165"/>
      <mass value="40.075"/>
      <inertia ixx="0.44959" ixy="-0.005113" ixz="0.017804" iyy="0.46194" iyz="-0.00061969" izz="0.78515"/>
    </inertial>
    <visual>
      <origin rpy="0 0 0" xyz="0 0 0"/>
      <geometry>
        <mesh filename="meshes/base_link.stl"/>
      </geometry>
      <material name="">
        <color rgba="0.745 0.203 0.482 1"/>
      </material>
    </visual>
    <collision>
      <origin rpy="0 0 0" xyz="0 0 0"/>
      <geometry>
        <mesh filename="meshes/base_link_simplified.stl" scale="0.1 0.1 0.1"/>
      </geometry>
    </collision>
  </link>

  <link name="xarm_base"/>
  <joint name="xarm_base_joint" type="fixed">
    <origin rpy="0 0 1.57" xyz="0.036105613000001 0 0.441000000000001"/>
    <parent link="base_link"/>
    <child link="link_base"/>
  </joint>

  <link name="link_base">
      <inertial>
        <origin xyz="0.0 0.0 0.09103" rpy="0 0 0" />
        <mass value="2.7" />
        <inertia
          ixx="0.00494875" ixy="-3.5E-06" ixz="1.25E-05"
          iyy="0.00494174" iyz="1.67E-06" izz="0.002219" />
      </inertial>
      <visual>
        <origin xyz="0 0 0" rpy="0 0 0"/>
        <geometry>
            <mesh filename="meshes/xarm/link_base.stl"/>
        </geometry>
        <material name="">
          <color rgba="1.0 1.0 1.0 1.0" />
        </material>
      </visual>
      <collision>
        <origin xyz="0 0 0.085" rpy="0 0 0"/>
        <geometry>
          <sphere radius="0.1"/>
        </geometry>
      </collision>
      <collision>
        <origin xyz="0 0 0.13" rpy="0 0 0"/>
        <geometry>
          <sphere radius="0.1"/>
        </geometry>
      </collision>
      <collision>
        <origin xyz="0 0 0.03" rpy="0 0 0"/>
        <geometry>
          <sphere radius="0.1"/>
        </geometry>
      </collision>
  </link>

<!--LINK 1-->

  <link name="link1">
      <inertial>
        <origin
          xyz=".00022 0.02951 -0.0124"
          rpy="0 0 0" />
        <mass value="2.3814" />
        <inertia ixx="0.0058562" ixy="-1.79e-05" ixz="3.55e-06"
                 iyy="0.0050316" iyz="-0.000888336" izz="0.003536652" />
      </inertial>
      <visual>
        <geometry>
          <mesh filename="meshes/xarm/link1.stl"/>
        </geometry>
        <origin xyz="0 0 0" rpy="0 0 0"/>
        <material name="">
          <color rgba="1.0 1.0 1.0 1.0" />
        </material>
      </visual>
      <collision>
        <origin xyz="0 0 -0.09" rpy="0 0 0"/>
        <geometry>
          <sphere radius="0.1"/>
        </geometry>
      </collision>
      <collision>
        <origin xyz="0 -0.003 -0.011" rpy="0 0 0"/>
        <geometry>
          <sphere radius="0.1"/>
        </geometry>
      </collision>
      <collision>
        <origin xyz="0 0 -0.05" rpy="0 0 0"/>
        <geometry>
          <sphere radius="0.1"/>
        </geometry>
      </collision>
      <collision>
        <origin xyz="0 0.041 0" rpy="0 0 0"/>
        <geometry>
          <sphere radius="0.1"/>
        </geometry>
      </collision>
  </link>

  <joint name="joint1" type="revolute">
    <parent link="link_base"/>
    <child link="link1"/>
    <origin xyz="0 0 0.267" rpy="0 0 0"/> 
    <axis xyz="0 0 1"/>
    <limit
      lower="-6.2831"
      upper="6.2831"
      effort="50.0"
      velocity="3.14"/>
    <dynamics damping="1.0" friction="1.0"/>
  </joint>

<!--LINK 2-->

    <link name="link2">
      <inertial>
        <origin
          xyz="0.03881 -0.22783 0.03496"
          rpy="0 0 0" />
        <mass value="2.2675" />
        <inertia
          ixx="0.028315776"
          ixy="0.005"
          ixz="0.00066546"
          iyy="0.0058"
          iyz="-0.0045741"
          izz="0.0273447" />
      </inertial>
      <visual>
        <origin xyz="0 0 0" rpy="0 0 0"/>
        <geometry>
          <mesh filename="meshes/xarm/link2.stl"/>
        </geometry>
        <material name="white_link2">
          <color rgba="1.0 1.0 1.0 1.0" />
        </material>
      </visual>
      <collision>
        <origin xyz="0 0 0.075" rpy="0 0 0"/>
        <geometry>
          <sphere radius="0.1"/>
        </geometry>
      </collision>
      <collision>
        <origin xyz="-0.022 -0.033 0.095" rpy="0 0 0"/>
        <geometry>
          <sphere radius="0.1"/>
        </geometry>
      </collision>
      <collision>
        <origin xyz="0.024 -0.029 0.096" rpy="0 0 0"/>
        <geometry>
          <sphere radius="0.1"/>
        </geometry>
      </collision>
      <collision>
        <origin xyz="0 -0.114 0.006" rpy="0 0 0"/>
        <geometry>
          <sphere radius="0.1"/>
        </geometry>
      </collision>
      <collision>
        <origin xyz="0 -0.108 0.079" rpy="0 0 0"/>
        <geometry>
          <sphere radius="0.1"/>
        </geometry>
      </collision>
      <collision>
        <origin xyz="0 -0.109 0.048" rpy="0 0 0"/>
        <geometry>
          <sphere radius="0.1"/>
        </geometry>
      </collision>
      <collision>
        <origin xyz="-0.024 -0.071 0.098" rpy="0 0 0"/>
        <geometry>
          <sphere radius="0.1"/>
        </geometry>
      </collision>
      <collision>
        <origin xyz="0.026 -0.07 0.097" rpy="0 0 0"/>
        <geometry>
          <sphere radius="0.1"/>
        </geometry>
      </collision>
      <collision>
        <origin xyz="0 -0.175 0" rpy="0 0 0"/>
        <geometry>
          <sphere radius="0.1"/>
        </geometry>
      </collision>
      <collision>
        <origin xyz="0 -0.219 -0.006" rpy="0 0 0"/>
        <geometry>
          <sphere radius="0.1"/>
        </geometry>
      </collision>
      <collision>
        <origin xyz="0.044 -0.288 -0.019" rpy="0 0 0"/>
        <geometry>
          <sphere radius="0.1"/>
        </geometry>
      </collision>
      <collision>
        <origin xyz="0.053 -0.285 0.028" rpy="0 0 0"/>
        <geometry>
          <sphere radius="0.1"/>
        </geometry>
      </collision>
      <collision>
        <origin xyz="0.018 -0.256 -0.019" rpy="0 0 0"/>
        <geometry>
          <sphere radius="0.1"/>
        </geometry>
      </collision>
    </link>

    <joint name="joint2" type="revolute">
      <parent link="link1"/>
      <child link="link2"/>
      <origin xyz="0 0 0" rpy="-1.5708 0 0" />
      <axis xyz="0 0 1"/>
      <limit
        lower="-2.059"
        upper="2.0944"
        effort="50.0"
        velocity="3.14"/>
      <dynamics damping="1.0" friction="1.0"/>
    </joint>

<!--LINK 3-->

    <link name="link3">
      <inertial>
        <origin
          xyz="0.07041 0.11631 0.0107"
          rpy="0 0 0" />
        <mass value="1.875" />
        <inertia
          ixx="0.0063483"
          ixy="-0.0015397"
          ixz="0.00096858"
          iyy="0.00379758"
          iyz="0.00186567"
          izz="0.00595768" />
      </inertial>
      <visual>
        <origin xyz="0 0 0" rpy="0 0 0"/>
        <geometry>
          <mesh filename="meshes/xarm/link3.stl"/>
        </geometry>
        <material name="">
          <color rgba="1.0 1.0 1.0 1.0" />
        </material>
      </visual>
      <collision>
        <origin xyz="0.001 0.0 0.068" rpy="0 0 0"/>
        <geometry><sphere radius="0.1"/></geometry>
      </collision>
      <collision>
        <origin xyz="0.039 0.014 0.086" rpy="0 0 0"/>
        <geometry><sphere radius="0.1"/></geometry>
      </collision>
      <collision>
        <origin xyz="0.012 0.04 0.083" rpy="0 0 0"/>
        <geometry><sphere radius="0.1"/></geometry>
      </collision>
      <collision>
        <origin xyz="0.034 0.061 0.082" rpy="0 0 0"/>
        <geometry><sphere radius="0.1"/></geometry>
      </collision>
      <collision>
        <origin xyz="0.058 0.041 0.083" rpy="0 0 0"/>
        <geometry><sphere radius="0.1"/></geometry>
      </collision>
      <collision>
        <origin xyz="0.074 0.08 0.066" rpy="0 0 0"/>
        <geometry><sphere radius="0.1"/></geometry>
      </collision>
      <collision>
        <origin xyz="0.077 0.086 0.01" rpy="0 0 0"/>
        <geometry><sphere radius="0.1"/></geometry>
      </collision>
      <collision>
        <origin xyz="0.077 0.134 -0.002" rpy="0 0 0"/>
        <geometry><sphere radius="0.1"/></geometry>
      </collision>
      <collision>
        <origin xyz="0 0 0" rpy="0 0 0"/>
        <geometry><sphere radius="0.1"/></geometry>
      </collision>
    </link>

    <joint name="joint3" type="revolute">
      <parent link="link2"/>
      <child link="link3"/>
      <origin xyz="0.0535 -0.2845 0" rpy="0 0 0"/>
      <axis xyz="0 0 1"/>
      <limit
        lower="-3.927"
        upper="0.19198"
        effort="32.0"
        velocity="3.14"/>
      <dynamics damping="1.0" friction="1.0"/>
    </joint>

<!--LINK 4-->

    <link name="link4">
      <inertial>
        <origin
          xyz="-0.00018 0.01798 -0.02291"
          rpy="0 0 0" />
        <mass value="1.3192" />
        <inertia
          ixx="0.004896"
          ixy="-6.925e-06"
          ixz="-1.418e-05"
          iyy="0.00445694"
          iyz="-0.00023186"
          izz="0.00134332" />
      </inertial>
      <visual>
        <geometry>
          <mesh filename="meshes/xarm/link4.stl"/>
        </geometry>
        <origin xyz="0 0 0" rpy="0 0 0"/>
        <material name="">
          <color rgba="1.0 1.0 1.0 1.0" />
        </material>
      </visual>
      <collision>
          <origin xyz="-0.001 0.0 -0.158" rpy="0 0 0"/>
          <geometry><sphere radius="0.1"/></geometry>
        </collision>
        <collision>
          <origin xyz="0.017 0.04 -0.119" rpy="0 0 0"/>
          <geometry><sphere radius="0.1"/></geometry>
        </collision>
        <collision>
          <origin xyz="-0.017 0.041 -0.115" rpy="0 0 0"/>
          <geometry><sphere radius="0.1"/></geometry>
        </collision>
        <collision>
          <origin xyz="-0.001 0.058 -0.093" rpy="0 0 0"/>
          <geometry><sphere radius="0.1"/></geometry>
        </collision>
        <collision>
          <origin xyz="0.0 0.05 -0.005" rpy="0 0 0"/>
          <geometry><sphere radius="0.1"/></geometry>
        </collision>
        <collision>
          <origin xyz="0.009 0.028 0.001" rpy="0 0 0"/>
          <geometry><sphere radius="0.1"/></geometry>
        </collision>
        <collision>
          <origin xyz="0.0 0.073 -0.054" rpy="0 0 0"/>
          <geometry><sphere radius="0.1"/></geometry>
        </collision>
    </link>

    <joint name="joint4" type="revolute">
      <parent link="link3"/>
      <child link="link4"/>
      <origin xyz="0.0775 0.3425 0" rpy="-1.5708 0 0"/>
      <axis xyz="0 0 1"/>
      <limit
        lower="-6.2831"
        upper="6.2831"
        effort="32.0"
        velocity="3.14"/>
      <dynamics damping="1.0" friction="1.0"/>
    </joint>

<!--LINK 5-->

    <link name="link5">
      <inertial>
        <origin
          xyz="0.0651 0.03096 0.00315"
          rpy="0 0 0" />
        <mass value="1.33854" />
        <inertia
          ixx="0.00146378"
          ixy="-0.000450624"
          ixz="0.000284306"
          iyy="0.00184192"
          iyz="0.000130866"
          izz="0.002333524" />
      </inertial>
      <visual>
        <geometry>
          <mesh filename="meshes/xarm/link5.stl"/>
        </geometry>
        <origin xyz="0 0 0" rpy="0 0 0"/>
        <material name="">
          <color rgba="1.0 1.0 1.0 1.0" />
        </material>
      </visual>
      <collision>
        <origin xyz="0.005 -0.001 0.019" rpy="0 0 0"/>
        <geometry><sphere radius="0.1"/></geometry>
      </collision>
      <collision>
        <origin xyz="0.071 0.003 0.002" rpy="0 0 0"/>
        <geometry><sphere radius="0.1"/></geometry>
      </collision>
      <collision>
        <origin xyz="0.08 0.041 0.001" rpy="0 0 0"/>
        <geometry><sphere radius="0.1"/></geometry>
      </collision>
    </link>

    <joint name="joint5" type="revolute">
      <parent link="link4"/>
      <child link="link5"/>
      <origin xyz="0 0 0" rpy="1.5708 0 0"/>
      <axis xyz="0 0 1"/>
      <limit
        lower="-1.69297"
        upper="3.1416"
        effort="32.0"
        velocity="3.14"/>
      <dynamics damping="1.0" friction="1.0"/>
    </joint>

<!--LINK 6-->

    <link name="link6">
    <inertial>
      <origin
        xyz="0 -0.00677 -0.01098"
        rpy="0 0 0" />
      <mass value="0.17" />
      <inertia
        ixx="9.3e-05"
        ixy="-0.0"
        ixz="-0.0"
        iyy="5.87e-05"
        iyz="-3.6e-06"
        izz="0.000132" />
    </inertial>
      <visual>
        <geometry>
          <mesh filename="meshes/xarm/link6.stl"/>
        </geometry>
        <origin xyz="0 0 0" rpy="0 0 0"/>
        <material name="">
          <color rgba="0.753 0.753 0.753 1.0" />
        </material>
      </visual>
      <collision>
        <origin xyz="0.0 0.0 -0.02" rpy="0 0 0"/>
        <geometry><sphere radius="0.1"/></geometry>
      </collision>
    </link>

    <joint name="joint6" type="revolute">
      <parent link="link5"/>
      <child link="link6"/>
      <origin xyz="0.076 0.097 0" rpy="-1.5708 0 0"/>
      <axis xyz="0 0 1"/>
      <limit
        lower="-6.2831"
        upper="6.2831"
        effort="20.0"
        velocity="3.14"/>
      <dynamics damping="1.0" friction="1.0"/>
    </joint>

    <link name="link_eef" />
    <joint name="joint_eef" type="fixed">
      <origin xyz="0 0 0" rpy="0 0 0" />
      <parent link="link6" />
      <child link="link_eef" />
    </joint>



  <joint name="gripper_grasp_joint" type="fixed">
    <parent link="link_eef"/>
    <child link="gripper_grasp_frame"/>
    <origin rpy="0 0 -0.7854" xyz="0 0 0"/>
  </joint>
  <link name="gripper_grasp_frame"> </link>

  <joint name="gripper_fix" type="fixed">
    <parent link="link_eef"/>
    <child link="gripper"/>
    <origin rpy="0 0 3.926" xyz="0 0 0.046"/>
  </joint>

  <link name="gripper">
    <inertial>
      <origin rpy="0 0 0" xyz="0.00033783 -0.0065249 0.0057345"/>
      <mass value="0.43538"/>
      <inertia ixx="0.00028883" ixy="-1.3378E-06" ixz="-7.8684E-07" iyy="0.0016861" iyz="-7.2811E-06" izz="0.0015525"/>
    </inertial>
    <visual>
      <origin rpy="0 0 0" xyz="0 0 0"/>
      <geometry>
        <mesh filename="meshes/gripper/gripper.stl"/>
      </geometry>
      <material name="">
        <color rgba="1 1 1 1"/>
      </material>
    </visual>
    <collision>
      <origin rpy="0 0 0" xyz="0 0 0"/>
      <geometry>
        <mesh filename="meshes/gripper/gripper.stl"/>
      </geometry>
    </collision>
  </link>

  <link name="right_finger">
    <inertial>
      <origin rpy="0 0 0" xyz="-0.0042467 -4.6842E-05 0.048292"/>
      <mass value="0.1028"/>
      <inertia ixx="8.1099e-05" ixy="3.8202e-08" ixz="1.9384e-06" iyy="7.2688e-05" iyz="-2.3121e-07" izz="1.8782e-05"/>
    </inertial>
    <visual>
      <origin rpy="0 0 0" xyz="0 0 0"/>
      <geometry>
        <mesh filename="meshes/gripper/right_finger.stl"/>
      </geometry>
      <material name="">
        <color rgba="1 1 1 1"/>
      </material>
    </visual>
    <collision>
      <origin rpy="0 0 0" xyz="0 0 0"/>
      <geometry>
        <mesh filename="meshes/gripper/right_finger.stl"/>
      </geometry>
    </collision>
  </link>

  <link name="left_finger">
    <inertial>
      <origin rpy="0 0 0" xyz="0.0042467 4.6842E-05 0.048292"/>
      <mass value="0.1028"/>
      <inertia ixx="8.1099e-05" ixy="3.8202e-08" ixz="-1.9384e-06" iyy="7.2688e-05" iyz="2.3121e-07" izz="1.8782e-05"/>
    </inertial>
    <visual>
      <origin rpy="0 0 0" xyz="0 0 0"/>
      <geometry>
        <mesh filename="meshes/gripper/left_finger.stl"/>
      </geometry>
      <material name="">
        <color rgba="1 1 1 1"/>
      </material>
    </visual>
    <collision>
      <origin rpy="0 0 0" xyz="0 0 0"/>
      <geometry>
        <mesh filename="meshes/gripper/left_finger.stl"/>
      </geometry>
    </collision>
  </link>

  <joint name="rightfinger" type="prismatic">
    <origin rpy="0 0 0" xyz="-0.069 0 0.017"/>
    <parent link="gripper"/>
    <child link="right_finger"/>
    <axis xyz="1 0 0"/>
    <limit effort="1" lower="0" upper="0.056" velocity="8"/>
  </joint>
  <joint name="leftfinger" type="prismatic">
    <origin rpy="0 0 0" xyz="0.069 0 0.017"/>
    <parent link="gripper"/>
    <child link="left_finger"/>
    <axis xyz="-1 0 0"/>
    <limit effort="1" lower="0" upper="0.056" velocity="8"/>
    <mimic joint="rightfinger" multiplier="1" offset="0"/>
  </joint>


  <link name="zed_camera_link">
    <inertial>
      <origin rpy="0 0 0" xyz="0.00022189 -2.7346E-06 1.8693E-05"/>
      <mass value="0.230"/>
      <inertia ixx="0.00038053" ixy="2.1426E-09" ixz="-8.1327E-08" iyy="2.3258E-05" iyz="6.6645E-09" izz="0.00038297"/>
    </inertial>
    <visual>
      <origin rpy="0 0 0" xyz="0 0 0"/>
      <geometry>
        <mesh filename="meshes/gripper/zed.stl"/>
      </geometry>
      <material name="">
        <color rgba="0.102 0.102 0.102 1"/>
      </material>
    </visual>
    <collision>
      <origin rpy="0 0 0" xyz="0 0 0"/>
      <geometry>
        <mesh filename="meshes/gripper/zed.stl"/>
      </geometry>
    </collision>
  </link>

  <joint name="zed_camera_joint" type="fixed">
    <origin rpy="0 -0.7854 -1.5708" xyz="-0.0045 -0.063576 0.0"/>
    <!--xyz="0 -0.095626 -0.005"-->
    <parent link="gripper"/>
    <child link="zed_camera_link"/>
    <axis xyz="0 0 0"/>
  </joint>


</robot>
