<?xml version="1.0" encoding="utf-8"?>

<robot name="xarm6_urdf"> params="
    joint1_lower_limit:=${-2.0*pi}  joint1_upper_limit:=${2.0*pi}
    joint2_lower_limit:=${-2.059}  joint2_upper_limit:=${2.0944}
    joint3_lower_limit:=${-3.927}  joint3_upper_limit:=${0.19198}
    joint4_lower_limit:=${-2.0*pi}  joint4_upper_limit:=${2.0*pi}
    joint5_lower_limit:=${-1.69297}  joint5_upper_limit:=${pi}
    joint6_lower_limit:=${-2.0*pi}  joint6_upper_limit:=${2.0*pi}
    model_num:=0
    inertial_params_filename:='' kinematics_params_filename:='' "

    <!-- define property ****usar mesh del visual y el end tool normal*****-->
    <xacro:if value="${model_num >= 1305 and model_num != 1380}">
      <xacro:property name="visual_dir" value="xarm6_1305/visual"/>
      <xacro:property name="collision_dir" value="xarm6_1305/collision"/>
      <xacro:property name="add_mesh_suffix" value="false"/>
      <xacro:property name="collison_mesh_suffix" value="obj"/>
      <xacro:property name="link6_visual" value="xarm6_1305/visual/link6"/>
      <xacro:property name="link6_collision" value="xarm6_1305/collision/link6"/>
    </xacro:if>
    <xacro:unless value="${model_num >= 1305 and model_num != 1380}">
      <xacro:property name="visual_dir" value="xarm6/visual"/>
      <xacro:property name="collision_dir" value="xarm6/visual"/>
      <xacro:property name="add_mesh_suffix" value="true"/>
      <xacro:property name="collison_mesh_suffix" value="stl"/>
      <xacro:if value="${model_num >= 1300}">
        <xacro:property name="link6_visual" value="end_tool/visual/end_tool_1300"/>
        <xacro:property name="link6_collision" value="end_tool/collision/end_tool_1300"/>
      </xacro:if>
      <xacro:unless value="${model_num >= 1300}">
        <xacro:property name="link6_visual" value="xarm6/visual/link6"/>
        <xacro:property name="link6_collision" value="end_tool/collision/end_tool"/>
      </xacro:unless>
    </xacro:unless>
    
    <!-- load params and define property -->
    <xacro:property name="default_inertial_params_filename" value="xarm6_type6_HT_BR2"/>
    <xacro:if value="${inertial_params_filename != ''}">
      <xacro:property name="link_inertial_params_file" value="$(find xarm_description)/config/link_inertial/${inertial_params_filename}.yaml"/>
    </xacro:if>
    <xacro:unless value="${inertial_params_filename != ''}">
      <xacro:property name="link_inertial_params_file" value="$(find xarm_description)/config/link_inertial/${default_inertial_params_filename}.yaml"/>
    </xacro:unless>
    <xacro:if value="${use_xacro_load_yaml}">
      <xacro:property name="inertial_params" value="${xacro.load_yaml(link_inertial_params_file)}"/>
      <xacro:property name="kinematics_config" value="${xacro.load_yaml(kinematics_params_filename)}"/>
    </xacro:if>
    <xacro:unless value="${use_xacro_load_yaml}">
      <xacro:property name="inertial_params" value="${load_yaml(link_inertial_params_file)}"/>
      <xacro:property name="kinematics_config" value="${load_yaml(kinematics_params_filename)}"/>
    </xacro:unless>
    <xacro:property name="kinematics_params" value="${kinematics_config['kinematics']}"/>
    


    <link name="link_base">
      <inertial>
        <origin xyz="0.0 0.0 0.09103" rpy="0 0 0" />
        <mass value="2.7" />
        <inertia
          ixx="0.00494875" ixy="-3.5E-06" ixz="1.25E-05"
          iyy="0.00494174" iyz="1.67E-06" izz="0.002219" />
      </inertial>
      <visual>
        <origin xyz="0 0 0" rpy="0 0 0"/>
        <geometry>
            <mesh filename="xarm6/visual/link_base.stl"/>
        </geometry>
        <material name="">
          <color rgba="1.0 1.0 1.0 1.0" />
        </material>
      </visual>
      <collision>
        <origin xyz="0 0 0" rpy="0 0 0"/>
        <geometry>
          <mesh filename="xarm6/visual/link_base.stl"/>
        </geometry>
      </collision>
    </link>

    <link name="link1">
      <xacro:common_link_inertial 
        link_inertial_params="${inertial_params['link1']}" 
        origin_rpy="0 0 0"/>
      <xacro:common_link_visual 
        mesh_filename="${visual_dir}/link1"  
        origin_xyz="0 0 0" 
        origin_rpy="0 0 0"
        material_name="White" />
      <xacro:common_link_collision 
        mesh_filename="${collision_dir}/link1"  
        add_mesh_suffix="${add_mesh_suffix}" 
        other_mesh_suffix="${collison_mesh_suffix}"
        origin_xyz="0 0 0" 
        origin_rpy="0 0 0" />
    </link>

    <joint name="joint1" type="revolute">
      <parent link="link_base"/>
      <child link="link1"/>
      <!-- <origin xyz="0 0 0.267" rpy="0 0 0"/> -->
      <xacro:common_joint_origin joint_kinematic_params="${kinematics_params['joint1']}" />
      <axis xyz="0 0 1"/>
      <limit
        lower="${joint1_lower_limit}"
        upper="${joint1_upper_limit}"
        effort="50.0"
        velocity="3.14"/>
      <dynamics damping="1.0" friction="1.0"/>
    </joint>

    <link name="link2">
      <xacro:common_link_inertial 
        link_inertial_params="${inertial_params['link2']}" 
        origin_rpy="0 0 0"/>
      <xacro:common_link_visual 
        mesh_filename="${visual_dir}/link2"  
        origin_xyz="0 0 0" 
        origin_rpy="0 0 0"
        material_name="White" />
      <xacro:common_link_collision 
        mesh_filename="${collision_dir}/link2"  
        add_mesh_suffix="${add_mesh_suffix}" 
        other_mesh_suffix="${collison_mesh_suffix}"
        origin_xyz="0 0 0" 
        origin_rpy="0 0 0" />
    </link>

    <joint name="joint2" type="revolute">
      <parent link="link1"/>
      <child link="link2"/>
      <!-- <origin xyz="0 0 0" rpy="-1.5708 0 0" /> -->
      <xacro:common_joint_origin joint_kinematic_params="${kinematics_params['joint2']}" />
      <axis xyz="0 0 1"/>
      <limit
        lower="${joint2_lower_limit}"
        upper="${joint2_upper_limit}"
        effort="50.0"
        velocity="3.14"/>
      <dynamics damping="1.0" friction="1.0"/>
    </joint>

    <link name="link3">
      <xacro:common_link_inertial 
        link_inertial_params="${inertial_params['link3']}" 
        origin_rpy="0 0 0"/>
      <xacro:common_link_visual 
        mesh_filename="${visual_dir}/link3"  
        origin_xyz="0 0 0" 
        origin_rpy="0 0 0"
        material_name="White" />
      <xacro:common_link_collision 
        mesh_filename="${collision_dir}/link3"  
        add_mesh_suffix="${add_mesh_suffix}" 
        other_mesh_suffix="${collison_mesh_suffix}"
        origin_xyz="0 0 0" 
        origin_rpy="0 0 0" />
    </link>

    <joint name="joint3" type="revolute">
      <parent link="link2"/>
      <child link="link3"/>
      <!-- <origin xyz="0.0535 -0.2845 0" rpy="0 0 0"/> -->
      <xacro:common_joint_origin joint_kinematic_params="${kinematics_params['joint3']}" />
      <axis xyz="0 0 1"/>
      <limit
        lower="${joint3_lower_limit}"
        upper="${joint3_upper_limit}"
        effort="32.0"
        velocity="3.14"/>
      <dynamics damping="1.0" friction="1.0"/>
    </joint>

    <link name="link4">
      <xacro:common_link_inertial 
        link_inertial_params="${inertial_params['link4']}" 
        origin_rpy="0 0 0"/>
      <xacro:common_link_visual 
        mesh_filename="${visual_dir}/link4"  
        origin_xyz="0 0 0" 
        origin_rpy="0 0 0"
        material_name="White" />
      <xacro:common_link_collision 
        mesh_filename="${collision_dir}/link4"  
        add_mesh_suffix="${add_mesh_suffix}" 
        other_mesh_suffix="${collison_mesh_suffix}"
        origin_xyz="0 0 0" 
        origin_rpy="0 0 0" />
    </link>

    <joint name="joint4" type="revolute">
      <parent link="link3"/>
      <child link="link4"/>
      <!-- <origin xyz="0.0775 0.3425 0" rpy="-1.5708 0 0"/> -->
      <xacro:common_joint_origin joint_kinematic_params="${kinematics_params['joint4']}" />
      <axis xyz="0 0 1"/>
      <limit
        lower="${joint4_lower_limit}"
        upper="${joint4_upper_limit}"
        effort="32.0"
        velocity="3.14"/>
      <dynamics damping="1.0" friction="1.0"/>
    </joint>

    <link name="link5">
      <xacro:common_link_inertial 
        link_inertial_params="${inertial_params['link5']}" 
        origin_rpy="0 0 0"/>
      <xacro:common_link_visual 
        mesh_filename="${visual_dir}/link5"  
        origin_xyz="0 0 0" 
        origin_rpy="0 0 0"
        material_name="White" />
      <xacro:common_link_collision 
        mesh_filename="${collision_dir}/link5"  
        add_mesh_suffix="${add_mesh_suffix}" 
        other_mesh_suffix="${collison_mesh_suffix}"
        origin_xyz="0 0 0" 
        origin_rpy="0 0 0" />
    </link>

    <joint name="joint5" type="revolute">
      <parent link="link4"/>
      <child link="link5"/>
      <xacro:common_joint_origin joint_kinematic_params="${kinematics_params['joint5']}" />
      <axis xyz="0 0 1"/>
      <limit
        lower="${joint5_lower_limit}"
        upper="${joint5_upper_limit}"
        effort="32.0"
        velocity="3.14"/>
      <dynamics damping="1.0" friction="1.0"/>
    </joint>

    <link name="link6">
      <xacro:common_link_inertial 
        link_inertial_params="${inertial_params['link6']}" 
        origin_rpy="0 0 0"/>
      <xacro:common_link_visual 
        mesh_filename="${link6_visual}"  
        origin_xyz="0 0 0" 
        origin_rpy="0 0 0"
        material_name="Silver" />
      <xacro:common_link_collision 
        mesh_filename="${link6_collision}"  
        add_mesh_suffix="${add_mesh_suffix}" 
        other_mesh_suffix="${collison_mesh_suffix}"
        origin_xyz="0 0 0" 
        origin_rpy="0 0 0" />
    </link>

    <joint name="joint6" type="revolute">
      <parent link="link5"/>
      <child link="link6"/>
      <!-- <origin xyz="0.076 0.097 0" rpy="-1.5708 0 0"/> -->
      <xacro:common_joint_origin joint_kinematic_params="${kinematics_params['joint6']}" />
      <axis xyz="0 0 1"/>
      <limit
        lower="${joint6_lower_limit}"
        upper="${joint6_upper_limit}"
        effort="20.0"
        velocity="3.14"/>
      <dynamics damping="1.0" friction="1.0"/>
    </joint>

    <!-- <link name="link_eef" />
    <joint name="joint_eef" type="fixed">
      <origin xyz="0 0 0" rpy="0 0 0" />
      <parent link="link6" />
      <child link="link_eef" />
    </joint> -->
  
  </xacro:macro>
</robot>